Workbook

Sheet Precios_Para_Comunicar
A1: Nombre_Comercial | B1: Producto | C1: Color | D1: Categoria | E1: Costo | F1: B2C | G1: Muestra | H1: Partner (1u) | I1: Starter (5-9u) | J1: Pro (10-20u) | K1: Drop (30-99u) | L1: Bulk (100+u) | M1: Margen%_Partner | N1: Margen%_Starter | O1: Margen%_Pro | P1: Margen%_Drop | Q1: Margen%_Bulk
B2: Buzo Cuello Redondo | C2: Blanco | D2: crewneck | E2: =Detalle_SKU_Con_Margenes!F2 -> 24100 | F2: 43000 | G2: 32200 | H2: =Detalle_SKU_Con_Margenes!I2 -> 32200 | I2: =Detalle_SKU_Con_Margenes!J2 -> 31200 | J2: =Detalle_SKU_Con_Margenes!K2 -> 30200 | K2: =Detalle_SKU_Con_Margenes!L2 -> 29200 | L2: =Detalle_SKU_Con_Margenes!M2 -> 28200 | M2: =(H2-$E2)/H2 -> 0.2515528 | N2: =(I2-$E2)/I2 -> 0.2275641 | O2: =(J2-$E2)/J2 -> 0.20198675 | P2: =(K2-$E2)/K2 -> 0.17465753 | Q2: =(L2-$E2)/L2 -> 0.14539007
B3: Buzo Cuello Redondo | C3: Negro | D3: crewneck | E3: =Detalle_SKU_Con_Margenes!F8 -> 28170 | F3: 43000 | G3: 32200 | H3: =Detalle_SKU_Con_Margenes!I8 -> 32200 | I3: =Detalle_SKU_Con_Margenes!J8 -> 31200 | J3: =Detalle_SKU_Con_Margenes!K8 -> 30200 | K3: =Detalle_SKU_Con_Margenes!L8 -> 29200 | L3: =Detalle_SKU_Con_Margenes!M8 -> 28200 | M3: =(H3-$E3)/H3 -> 0.12515528 | N3: =(I3-$E3)/I3 -> 0.097115385 | O3: =(J3-$E3)/J3 -> 0.067218543 | P3: =(K3-$E3)/K3 -> 0.035273973 | Q3: =(L3-$E3)/L3 -> 0.0010638298
B4: Buzo Cuello Redondo | C4: Stone Wash | D4: crewneck | E4: =Detalle_SKU_Con_Margenes!F14 -> 28170 | F4: 43000 | G4: 32200 | H4: =Detalle_SKU_Con_Margenes!I14 -> 32200 | I4: =Detalle_SKU_Con_Margenes!J14 -> 31200 | J4: =Detalle_SKU_Con_Margenes!K14 -> 30200 | K4: =Detalle_SKU_Con_Margenes!L14 -> 29200 | L4: =Detalle_SKU_Con_Margenes!M14 -> 28200 | M4: =(H4-$E4)/H4 -> 0.12515528 | N4: =(I4-$E4)/I4 -> 0.097115385 | O4: =(J4-$E4)/J4 -> 0.067218543 | P4: =(K4-$E4)/K4 -> 0.035273973 | Q4: =(L4-$E4)/L4 -> 0.0010638298
B5: Buzo Hoodie Unisex | C5: Blanco | D5: hoodie | E5: =Detalle_SKU_Con_Margenes!F20 -> 25100 | F5: 55000 | G5: 38700 | H5: =Detalle_SKU_Con_Margenes!I20 -> 38700 | I5: =Detalle_SKU_Con_Margenes!J20 -> 36600 | J5: =Detalle_SKU_Con_Margenes!K20 -> 34500 | K5: =Detalle_SKU_Con_Margenes!L20 -> 32400 | L5: =Detalle_SKU_Con_Margenes!M20 -> 30300 | M5: =(H5-$E5)/H5 -> 0.35142119 | N5: =(I5-$E5)/I5 -> 0.31420765 | O5: =(J5-$E5)/J5 -> 0.27246377 | P5: =(K5-$E5)/K5 -> 0.22530864 | Q5: =(L5-$E5)/L5 -> 0.17161716
B6: Buzo Hoodie Unisex | C6: Negro | D6: hoodie | E6: =Detalle_SKU_Con_Margenes!F26 -> 29170 | F6: 55000 | G6: 38700 | H6: =Detalle_SKU_Con_Margenes!I26 -> 38700 | I6: =Detalle_SKU_Con_Margenes!J26 -> 36600 | J6: =Detalle_SKU_Con_Margenes!K26 -> 34500 | K6: =Detalle_SKU_Con_Margenes!L26 -> 32400 | L6: =Detalle_SKU_Con_Margenes!M26 -> 30300 | M6: =(H6-$E6)/H6 -> 0.24625323 | N6: =(I6-$E6)/I6 -> 0.20300546 | O6: =(J6-$E6)/J6 -> 0.15449275 | P6: =(K6-$E6)/K6 -> 0.099691358 | Q6: =(L6-$E6)/L6 -> 0.037293729
B7: Buzo Hoodie Unisex | C7: Stone Wash | D7: hoodie | E7: =Detalle_SKU_Con_Margenes!F32 -> 30170 | F7: 55000 | G7: 38700 | H7: =Detalle_SKU_Con_Margenes!I32 -> 38700 | I7: =Detalle_SKU_Con_Margenes!J32 -> 36600 | J7: =Detalle_SKU_Con_Margenes!K32 -> 34500 | K7: =Detalle_SKU_Con_Margenes!L32 -> 32400 | L7: =Detalle_SKU_Con_Margenes!M32 -> 30300 | M7: =(H7-$E7)/H7 -> 0.22041344 | N7: =(I7-$E7)/I7 -> 0.17568306 | O7: =(J7-$E7)/J7 -> 0.12550725 | P7: =(K7-$E7)/K7 -> 0.06882716 | Q7: =(L7-$E7)/L7 -> 0.004290429
B8: Buzo Hoodie Unisex | C8: Caramel | D8: hoodie | E8: =Detalle_SKU_Con_Margenes!F38 -> 29170 | F8: 55000 | G8: 38700 | H8: =Detalle_SKU_Con_Margenes!I38 -> 38700 | I8: =Detalle_SKU_Con_Margenes!J38 -> 36600 | J8: =Detalle_SKU_Con_Margenes!K38 -> 34500 | K8: =Detalle_SKU_Con_Margenes!L38 -> 32400 | L8: =Detalle_SKU_Con_Margenes!M38 -> 30300 | M8: =(H8-$E8)/H8 -> 0.24625323 | N8: =(I8-$E8)/I8 -> 0.20300546 | O8: =(J8-$E8)/J8 -> 0.15449275 | P8: =(K8-$E8)/K8 -> 0.099691358 | Q8: =(L8-$E8)/L8 -> 0.037293729
B9: Buzo Hoodie Unisex | C9: Crema | D9: hoodie | E9: =Detalle_SKU_Con_Margenes!F43 -> 29170 | F9: 55000 | G9: 38700 | H9: =Detalle_SKU_Con_Margenes!I43 -> 38700 | I9: =Detalle_SKU_Con_Margenes!J43 -> 36600 | J9: =Detalle_SKU_Con_Margenes!K43 -> 34500 | K9: =Detalle_SKU_Con_Margenes!L43 -> 32400 | L9: =Detalle_SKU_Con_Margenes!M43 -> 30300 | M9: =(H9-$E9)/H9 -> 0.24625323 | N9: =(I9-$E9)/I9 -> 0.20300546 | O9: =(J9-$E9)/J9 -> 0.15449275 | P9: =(K9-$E9)/K9 -> 0.099691358 | Q9: =(L9-$E9)/L9 -> 0.037293729
B10: Buzo Hoodie Unisex | C10: Gris Melange | D10: hoodie | E10: =Detalle_SKU_Con_Margenes!F48 -> 29170 | F10: 55000 | G10: 38700 | H10: =Detalle_SKU_Con_Margenes!I48 -> 38700 | I10: =Detalle_SKU_Con_Margenes!J48 -> 36600 | J10: =Detalle_SKU_Con_Margenes!K48 -> 34500 | K10: =Detalle_SKU_Con_Margenes!L48 -> 32400 | L10: =Detalle_SKU_Con_Margenes!M48 -> 30300 | M10: =(H10-$E10)/H10 -> 0.24625323 | N10: =(I10-$E10)/I10 -> 0.20300546 | O10: =(J10-$E10)/J10 -> 0.15449275 | P10: =(K10-$E10)/K10 -> 0.099691358 | Q10: =(L10-$E10)/L10 -> 0.037293729
B11: Aura Oversize T-Shirt | C11: Blanco | D11: tee_oversize | E11: =Detalle_SKU_Con_Margenes!F53 -> 19000 | F11: 31000 | G11: 25400 | H11: 26600 | I11: 25900 | J11: 25100 | K11: 24300 | L11: 23600 | M11: =(H11-$E11)/H11 -> 0.28571429 | N11: =(I11-$E11)/I11 -> 0.26640927 | O11: =(J11-$E11)/J11 -> 0.24302789 | P11: =(K11-$E11)/K11 -> 0.218107 | Q11: =(L11-$E11)/L11 -> 0.19491525
B12: Aura Oversize T-Shirt | C12: Caramel | D12: tee_oversize | E12: =Detalle_SKU_Con_Margenes!F60 -> 23070 | F12: 31000 | G12: 25400 | H12: 26600 | I12: 25900 | J12: 25100 | K12: 24300 | L12: 23600 | M12: =(H12-$E12)/H12 -> 0.13270677 | N12: =(I12-$E12)/I12 -> 0.10926641 | O12: =(J12-$E12)/J12 -> 0.080876494 | P12: =(K12-$E12)/K12 -> 0.050617284 | Q12: =(L12-$E12)/L12 -> 0.022457627
B13: Aura Oversize T-Shirt | C13: Negro | D13: tee_oversize | E13: =Detalle_SKU_Con_Margenes!F64 -> 23070 | F13: 31000 | G13: 25400 | H13: 26600 | I13: 25900 | J13: 25100 | K13: 24300 | L13: 23600 | M13: =(H13-$E13)/H13 -> 0.13270677 | N13: =(I13-$E13)/I13 -> 0.10926641 | O13: =(J13-$E13)/J13 -> 0.080876494 | P13: =(K13-$E13)/K13 -> 0.050617284 | Q13: =(L13-$E13)/L13 -> 0.022457627
B14: Aura Oversize T-Shirt | C14: Stone Wash | D14: tee_oversize | E14: =Detalle_SKU_Con_Margenes!F71 -> 23470 | F14: 31000 | G14: 25400 | H14: 26600 | I14: 25900 | J14: 25100 | K14: 24300 | L14: 23600 | M14: =(H14-$E14)/H14 -> 0.11766917 | N14: =(I14-$E14)/I14 -> 0.093822394 | O14: =(J14-$E14)/J14 -> 0.064940239 | P14: =(K14-$E14)/K14 -> 0.034156379 | Q14: =(L14-$E14)/L14 -> 0.0055084746
B15: Aldea Classic Fit T-Shirt | C15: Blanco | D15: tee_classic | E15: =Detalle_SKU_Con_Margenes!F75 -> 18600 | F15: 28600 | G15: 25700 | H15: 25800 | I15: 25100 | J15: 24400 | K15: 23800 | L15: 23600 | M15: =(H15-$E15)/H15 -> 0.27906977 | N15: =(I15-$E15)/I15 -> 0.25896414 | O15: =(J15-$E15)/J15 -> 0.23770492 | P15: =(K15-$E15)/K15 -> 0.21848739 | Q15: =(L15-$E15)/L15 -> 0.21186441
B16: Aldea Classic Fit T-Shirt | C16: Negro | D16: tee_classic | E16: =Detalle_SKU_Con_Margenes!F80 -> 22670 | F16: 28600 | G16: 25700 | H16: 25800 | I16: 25100 | J16: 24400 | K16: 23800 | L16: 23600 | M16: =(H16-$E16)/H16 -> 0.12131783 | N16: =(I16-$E16)/I16 -> 0.096812749 | O16: =(J16-$E16)/J16 -> 0.070901639 | P16: =(K16-$E16)/K16 -> 0.047478992 | Q16: =(L16-$E16)/L16 -> 0.03940678
B17: Remera Clásica Mujer | C17: Blanca | D17: tee_classic | E17: =Detalle_SKU_Con_Margenes!F85 -> 18600 | F17: 28600 | G17: 25700 | H17: 25800 | I17: 25100 | J17: 24400 | K17: 23800 | L17: 23600 | M17: =(H17-$E17)/H17 -> 0.27906977 | N17: =(I17-$E17)/I17 -> 0.25896414 | O17: =(J17-$E17)/J17 -> 0.23770492 | P17: =(K17-$E17)/K17 -> 0.21848739 | Q17: =(L17-$E17)/L17 -> 0.21186441
B18: Remera Clásica Mujer | C18: Negra | D18: tee_classic | E18: =Detalle_SKU_Con_Margenes!F90 -> 22670 | F18: 28600 | G18: 25700 | H18: 25800 | I18: 25100 | J18: 24400 | K18: 23800 | L18: 23600 | M18: =(H18-$E18)/H18 -> 0.12131783 | N18: =(I18-$E18)/I18 -> 0.096812749 | O18: =(J18-$E18)/J18 -> 0.070901639 | P18: =(K18-$E18)/K18 -> 0.047478992 | Q18: =(L18-$E18)/L18 -> 0.03940678
B19: Remera Crop Mujer | C19: Amarillo | D19: crop | E19: =Detalle_SKU_Con_Margenes!F95 -> 18100 | F19: 23500 | G19: 19300 | H19: 20800 | I19: 20300 | J19: 19800 | K19: 19300 | L19: 18900 | M19: =(H19-$E19)/H19 -> 0.12980769 | N19: =(I19-$E19)/I19 -> 0.10837438 | O19: =(J19-$E19)/J19 -> 0.085858586 | P19: =(K19-$E19)/K19 -> 0.062176166 | Q19: =(L19-$E19)/L19 -> 0.042328042
B20: Remera Crop Mujer | C20: Chocolate | D20: crop | E20: =Detalle_SKU_Con_Margenes!F100 -> 18100 | F20: 23500 | G20: 19300 | H20: 20800 | I20: 20300 | J20: 19800 | K20: 19300 | L20: 18900 | M20: =(H20-$E20)/H20 -> 0.12980769 | N20: =(I20-$E20)/I20 -> 0.10837438 | O20: =(J20-$E20)/J20 -> 0.085858586 | P20: =(K20-$E20)/K20 -> 0.062176166 | Q20: =(L20-$E20)/L20 -> 0.042328042
B21: Remera Crop Mujer | C21: Gris Melange | D21: crop | E21: =Detalle_SKU_Con_Margenes!F105 -> 18100 | F21: 23500 | G21: 19300 | H21: 20800 | I21: 20300 | J21: 19800 | K21: 19300 | L21: 18900 | M21: =(H21-$E21)/H21 -> 0.12980769 | N21: =(I21-$E21)/I21 -> 0.10837438 | O21: =(J21-$E21)/J21 -> 0.085858586 | P21: =(K21-$E21)/K21 -> 0.062176166 | Q21: =(L21-$E21)/L21 -> 0.042328042
B22: Remera Crop Mujer | C22: Negra | D22: crop | E22: =Detalle_SKU_Con_Margenes!F95 -> 18100 | F22: 23500 | G22: 19300 | H22: 20800 | I22: 20300 | J22: 19800 | K22: 19300 | L22: 18900 | M22: =(H22-$E22)/H22 -> 0.12980769 | N22: =(I22-$E22)/I22 -> 0.10837438 | O22: =(J22-$E22)/J22 -> 0.085858586 | P22: =(K22-$E22)/K22 -> 0.062176166 | Q22: =(L22-$E22)/L22 -> 0.042328042
B23: Musculosa Bali | C23: Blanca | D23: tank | E23: ='Precios Tab Dreamfull-sheets'!$G$12 -> 18100 | F23: 21800 | G23: =H23 -> 20800 | H23: 20800 | I23: 20700 | J23: 20500 | K23: 20300 | L23: 20100 | M23: =(H23-$E23)/H23 -> 0.12980769 | N23: =(I23-$E23)/I23 -> 0.12560386 | O23: =(J23-$E23)/J23 -> 0.11707317 | P23: =(K23-$E23)/K23 -> 0.10837438 | Q23: =(L23-$E23)/L23 -> 0.099502488
B24: Musculosa Bali | C24: Gris | D24: tank | E24: ='Precios Tab Dreamfull-sheets'!$G$12 -> 18100 | F24: 21800 | G24: =H24 -> 20800 | H24: 20800 | I24: 20700 | J24: 20500 | K24: 20300 | L24: 20100 | M24: =(H24-$E24)/H24 -> 0.12980769 | N24: =(I24-$E24)/I24 -> 0.12560386 | O24: =(J24-$E24)/J24 -> 0.11707317 | P24: =(K24-$E24)/K24 -> 0.10837438 | Q24: =(L24-$E24)/L24 -> 0.099502488
B25: Musculosa Bali | C25: Negra | D25: tank | E25: ='Precios Tab Dreamfull-sheets'!$G$12 -> 18100 | F25: 21800 | G25: =H25 -> 20800 | H25: 20800 | I25: 20700 | J25: 20500 | K25: 20300 | L25: 20100 | M25: =(H25-$E25)/H25 -> 0.12980769 | N25: =(I25-$E25)/I25 -> 0.12560386 | O25: =(J25-$E25)/J25 -> 0.11707317 | P25: =(K25-$E25)/K25 -> 0.10837438 | Q25: =(L25-$E25)/L25 -> 0.099502488

Sheet Precios_Partners_Growth
A1: Precios Partners GROWTH — cercanos a costo (+$1.000 base, escalón −$200/tier)
A2: PRECIO UNICO POR PRODUCTO (no por color): se calcula sobre el COSTO DEL COLOR MAS CARO + delta. Partner=+1000, Starter=+800, Pro=+600, Drop=+400, Bulk=+200. Garantiza min. 8% de ahorro vs el precio Partner normal. Recalcula automaticamente.
A4: Producto | B4: Color | C4: Categoria | D4: Costo | E4: Partner (1u) | F4: Starter (5-9u) | G4: Pro (10-20u) | H4: Drop (30-99u) | I4: Bulk (100+u) | J4: Margen%_Partner | K4: Margen%_Starter | L4: Margen%_Pro | M4: Margen%_Drop | N4: Margen%_Bulk
A5: =Precios_Para_Comunicar!B2 -> Buzo Cuello Redondo | B5: =Precios_Para_Comunicar!C2 -> Blanco | C5: =Precios_Para_Comunicar!D2 -> crewneck | D5: =Precios_Para_Comunicar!E2 -> 24100 | E5: =Resumen_por_Producto!$D$2+1000 -> 29170 | F5: =Resumen_por_Producto!$D$2+800 -> 28970 | G5: =Resumen_por_Producto!$D$2+600 -> 28770 | H5: =Resumen_por_Producto!$D$2+400 -> 28570 | I5: =Resumen_por_Producto!$D$2+200 -> 28370 | J5: =(E5-$D5)/E5 -> 0.17380871 | K5: =(F5-$D5)/F5 -> 0.16810494 | L5: =(G5-$D5)/G5 -> 0.16232186 | M5: =(H5-$D5)/H5 -> 0.15645782 | N5: =(I5-$D5)/I5 -> 0.1505111
A6: =Precios_Para_Comunicar!B3 -> Buzo Cuello Redondo | B6: =Precios_Para_Comunicar!C3 -> Negro | C6: =Precios_Para_Comunicar!D3 -> crewneck | D6: =Precios_Para_Comunicar!E3 -> 28170 | E6: =Resumen_por_Producto!$D$2+1000 -> 29170 | F6: =Resumen_por_Producto!$D$2+800 -> 28970 | G6: =Resumen_por_Producto!$D$2+600 -> 28770 | H6: =Resumen_por_Producto!$D$2+400 -> 28570 | I6: =Resumen_por_Producto!$D$2+200 -> 28370 | J6: =(E6-$D6)/E6 -> 0.034281796 | K6: =(F6-$D6)/F6 -> 0.027614774 | L6: =(G6-$D6)/G6 -> 0.020855057 | M6: =(H6-$D6)/H6 -> 0.0140007 | N6: =(I6-$D6)/I6 -> 0.0070497004
A7: =Precios_Para_Comunicar!B4 -> Buzo Cuello Redondo | B7: =Precios_Para_Comunicar!C4 -> Stone Wash | C7: =Precios_Para_Comunicar!D4 -> crewneck | D7: =Precios_Para_Comunicar!E4 -> 28170 | E7: =Resumen_por_Producto!$D$2+1000 -> 29170 | F7: =Resumen_por_Producto!$D$2+800 -> 28970 | G7: =Resumen_por_Producto!$D$2+600 -> 28770 | H7: =Resumen_por_Producto!$D$2+400 -> 28570 | I7: =Resumen_por_Producto!$D$2+200 -> 28370 | J7: =(E7-$D7)/E7 -> 0.034281796 | K7: =(F7-$D7)/F7 -> 0.027614774 | L7: =(G7-$D7)/G7 -> 0.020855057 | M7: =(H7-$D7)/H7 -> 0.0140007 | N7: =(I7-$D7)/I7 -> 0.0070497004
A8: =Precios_Para_Comunicar!B5 -> Buzo Hoodie Unisex | B8: =Precios_Para_Comunicar!C5 -> Blanco | C8: =Precios_Para_Comunicar!D5 -> hoodie | D8: =Precios_Para_Comunicar!E5 -> 25100 | E8: =Resumen_por_Producto!$D$3+1000 -> 31170 | F8: =Resumen_por_Producto!$D$3+800 -> 30970 | G8: =Resumen_por_Producto!$D$3+600 -> 30770 | H8: =Resumen_por_Producto!$D$3+400 -> 30570 | I8: =Resumen_por_Producto!$D$3+200 -> 30370 | J8: =(E8-$D8)/E8 -> 0.19473853 | K8: =(F8-$D8)/F8 -> 0.18953826 | L8: =(G8-$D8)/G8 -> 0.18427039 | M8: =(H8-$D8)/H8 -> 0.1789336 | N8: =(I8-$D8)/I8 -> 0.17352651
A9: =Precios_Para_Comunicar!B6 -> Buzo Hoodie Unisex | B9: =Precios_Para_Comunicar!C6 -> Negro | C9: =Precios_Para_Comunicar!D6 -> hoodie | D9: =Precios_Para_Comunicar!E6 -> 29170 | E9: =Resumen_por_Producto!$D$3+1000 -> 31170 | F9: =Resumen_por_Producto!$D$3+800 -> 30970 | G9: =Resumen_por_Producto!$D$3+600 -> 30770 | H9: =Resumen_por_Producto!$D$3+400 -> 30570 | I9: =Resumen_por_Producto!$D$3+200 -> 30370 | J9: =(E9-$D9)/E9 -> 0.064164261 | K9: =(F9-$D9)/F9 -> 0.058120762 | L9: =(G9-$D9)/G9 -> 0.0519987 | M9: =(H9-$D9)/H9 -> 0.045796533 | N9: =(I9-$D9)/I9 -> 0.039512677
A10: =Precios_Para_Comunicar!B7 -> Buzo Hoodie Unisex | B10: =Precios_Para_Comunicar!C7 -> Stone Wash | C10: =Precios_Para_Comunicar!D7 -> hoodie | D10: =Precios_Para_Comunicar!E7 -> 30170 | E10: =Resumen_por_Producto!$D$3+1000 -> 31170 | F10: =Resumen_por_Producto!$D$3+800 -> 30970 | G10: =Resumen_por_Producto!$D$3+600 -> 30770 | H10: =Resumen_por_Producto!$D$3+400 -> 30570 | I10: =Resumen_por_Producto!$D$3+200 -> 30370 | J10: =(E10-$D10)/E10 -> 0.03208213 | K10: =(F10-$D10)/F10 -> 0.02583145 | L10: =(G10-$D10)/G10 -> 0.019499513 | M10: =(H10-$D10)/H10 -> 0.013084724 | N10: =(I10-$D10)/I10 -> 0.0065854462
A11: =Precios_Para_Comunicar!B8 -> Buzo Hoodie Unisex | B11: =Precios_Para_Comunicar!C8 -> Caramel | C11: =Precios_Para_Comunicar!D8 -> hoodie | D11: =Precios_Para_Comunicar!E8 -> 29170 | E11: =Resumen_por_Producto!$D$3+1000 -> 31170 | F11: =Resumen_por_Producto!$D$3+800 -> 30970 | G11: =Resumen_por_Producto!$D$3+600 -> 30770 | H11: =Resumen_por_Producto!$D$3+400 -> 30570 | I11: =Resumen_por_Producto!$D$3+200 -> 30370 | J11: =(E11-$D11)/E11 -> 0.064164261 | K11: =(F11-$D11)/F11 -> 0.058120762 | L11: =(G11-$D11)/G11 -> 0.0519987 | M11: =(H11-$D11)/H11 -> 0.045796533 | N11: =(I11-$D11)/I11 -> 0.039512677
A12: =Precios_Para_Comunicar!B9 -> Buzo Hoodie Unisex | B12: =Precios_Para_Comunicar!C9 -> Crema | C12: =Precios_Para_Comunicar!D9 -> hoodie | D12: =Precios_Para_Comunicar!E9 -> 29170 | E12: =Resumen_por_Producto!$D$3+1000 -> 31170 | F12: =Resumen_por_Producto!$D$3+800 -> 30970 | G12: =Resumen_por_Producto!$D$3+600 -> 30770 | H12: =Resumen_por_Producto!$D$3+400 -> 30570 | I12: =Resumen_por_Producto!$D$3+200 -> 30370 | J12: =(E12-$D12)/E12 -> 0.064164261 | K12: =(F12-$D12)/F12 -> 0.058120762 | L12: =(G12-$D12)/G12 -> 0.0519987 | M12: =(H12-$D12)/H12 -> 0.045796533 | N12: =(I12-$D12)/I12 -> 0.039512677
A13: =Precios_Para_Comunicar!B10 -> Buzo Hoodie Unisex | B13: =Precios_Para_Comunicar!C10 -> Gris Melange | C13: =Precios_Para_Comunicar!D10 -> hoodie | D13: =Precios_Para_Comunicar!E10 -> 29170 | E13: =Resumen_por_Producto!$D$3+1000 -> 31170 | F13: =Resumen_por_Producto!$D$3+800 -> 30970 | G13: =Resumen_por_Producto!$D$3+600 -> 30770 | H13: =Resumen_por_Producto!$D$3+400 -> 30570 | I13: =Resumen_por_Producto!$D$3+200 -> 30370 | J13: =(E13-$D13)/E13 -> 0.064164261 | K13: =(F13-$D13)/F13 -> 0.058120762 | L13: =(G13-$D13)/G13 -> 0.0519987 | M13: =(H13-$D13)/H13 -> 0.045796533 | N13: =(I13-$D13)/I13 -> 0.039512677
A14: =Precios_Para_Comunicar!B11 -> Aura Oversize T-Shirt | B14: =Precios_Para_Comunicar!C11 -> Blanco | C14: =Precios_Para_Comunicar!D11 -> tee_oversize | D14: =Precios_Para_Comunicar!E11 -> 19000 | E14: =Resumen_por_Producto!$D$4+1000 -> 24470 | F14: =Resumen_por_Producto!$D$4+800 -> 24270 | G14: =Resumen_por_Producto!$D$4+600 -> 24070 | H14: =Resumen_por_Producto!$D$4+400 -> 23870 | I14: =Resumen_por_Producto!$D$4+200 -> 23670 | J14: =(E14-$D14)/E14 -> 0.22353903 | K14: =(F14-$D14)/F14 -> 0.2171405 | L14: =(G14-$D14)/G14 -> 0.21063565 | M14: =(H14-$D14)/H14 -> 0.20402178 | N14: =(I14-$D14)/I14 -> 0.19729616
A15: =Precios_Para_Comunicar!B12 -> Aura Oversize T-Shirt | B15: =Precios_Para_Comunicar!C12 -> Caramel | C15: =Precios_Para_Comunicar!D12 -> tee_oversize | D15: =Precios_Para_Comunicar!E12 -> 23070 | E15: =Resumen_por_Producto!$D$4+1000 -> 24470 | F15: =Resumen_por_Producto!$D$4+800 -> 24270 | G15: =Resumen_por_Producto!$D$4+600 -> 24070 | H15: =Resumen_por_Producto!$D$4+400 -> 23870 | I15: =Resumen_por_Producto!$D$4+200 -> 23670 | J15: =(E15-$D15)/E15 -> 0.057212914 | K15: =(F15-$D15)/F15 -> 0.049443758 | L15: =(G15-$D15)/G15 -> 0.041545492 | M15: =(H15-$D15)/H15 -> 0.033514872 | N15: =(I15-$D15)/I15 -> 0.025348542
A16: =Precios_Para_Comunicar!B13 -> Aura Oversize T-Shirt | B16: =Precios_Para_Comunicar!C13 -> Negro | C16: =Precios_Para_Comunicar!D13 -> tee_oversize | D16: =Precios_Para_Comunicar!E13 -> 23070 | E16: =Resumen_por_Producto!$D$4+1000 -> 24470 | F16: =Resumen_por_Producto!$D$4+800 -> 24270 | G16: =Resumen_por_Producto!$D$4+600 -> 24070 | H16: =Resumen_por_Producto!$D$4+400 -> 23870 | I16: =Resumen_por_Producto!$D$4+200 -> 23670 | J16: =(E16-$D16)/E16 -> 0.057212914 | K16: =(F16-$D16)/F16 -> 0.049443758 | L16: =(G16-$D16)/G16 -> 0.041545492 | M16: =(H16-$D16)/H16 -> 0.033514872 | N16: =(I16-$D16)/I16 -> 0.025348542
A17: =Precios_Para_Comunicar!B14 -> Aura Oversize T-Shirt | B17: =Precios_Para_Comunicar!C14 -> Stone Wash | C17: =Precios_Para_Comunicar!D14 -> tee_oversize | D17: =Precios_Para_Comunicar!E14 -> 23470 | E17: =Resumen_por_Producto!$D$4+1000 -> 24470 | F17: =Resumen_por_Producto!$D$4+800 -> 24270 | G17: =Resumen_por_Producto!$D$4+600 -> 24070 | H17: =Resumen_por_Producto!$D$4+400 -> 23870 | I17: =Resumen_por_Producto!$D$4+200 -> 23670 | J17: =(E17-$D17)/E17 -> 0.040866367 | K17: =(F17-$D17)/F17 -> 0.032962505 | L17: =(G17-$D17)/G17 -> 0.024927295 | M17: =(H17-$D17)/H17 -> 0.016757436 | N17: =(I17-$D17)/I17 -> 0.0084495142
A18: =Precios_Para_Comunicar!B15 -> Aldea Classic Fit T-Shirt | B18: =Precios_Para_Comunicar!C15 -> Blanco | C18: =Precios_Para_Comunicar!D15 -> tee_classic | D18: =Precios_Para_Comunicar!E15 -> 18600 | E18: =Resumen_por_Producto!$D$5+1000 -> 23670 | F18: =Resumen_por_Producto!$D$5+800 -> 23470 | G18: =Resumen_por_Producto!$D$5+600 -> 23270 | H18: =Resumen_por_Producto!$D$5+400 -> 23070 | I18: =Resumen_por_Producto!$D$5+200 -> 22870 | J18: =(E18-$D18)/E18 -> 0.21419518 | K18: =(F18-$D18)/F18 -> 0.20749893 | L18: =(G18-$D18)/G18 -> 0.20068758 | M18: =(H18-$D18)/H18 -> 0.19375813 | N18: =(I18-$D18)/I18 -> 0.18670748
A19: =Precios_Para_Comunicar!B16 -> Aldea Classic Fit T-Shirt | B19: =Precios_Para_Comunicar!C16 -> Negro | C19: =Precios_Para_Comunicar!D16 -> tee_classic | D19: =Precios_Para_Comunicar!E16 -> 22670 | E19: =Resumen_por_Producto!$D$5+1000 -> 23670 | F19: =Resumen_por_Producto!$D$5+800 -> 23470 | G19: =Resumen_por_Producto!$D$5+600 -> 23270 | H19: =Resumen_por_Producto!$D$5+400 -> 23070 | I19: =Resumen_por_Producto!$D$5+200 -> 22870 | J19: =(E19-$D19)/E19 -> 0.042247571 | K19: =(F19-$D19)/F19 -> 0.034086067 | L19: =(G19-$D19)/G19 -> 0.025784272 | M19: =(H19-$D19)/H19 -> 0.017338535 | N19: =(I19-$D19)/I19 -> 0.0087450809
A20: =Precios_Para_Comunicar!B17 -> Remera Clásica Mujer | B20: =Precios_Para_Comunicar!C17 -> Blanca | C20: =Precios_Para_Comunicar!D17 -> tee_classic | D20: =Precios_Para_Comunicar!E17 -> 18600 | E20: =Resumen_por_Producto!$D$6+1000 -> 23670 | F20: =Resumen_por_Producto!$D$6+800 -> 23470 | G20: =Resumen_por_Producto!$D$6+600 -> 23270 | H20: =Resumen_por_Producto!$D$6+400 -> 23070 | I20: =Resumen_por_Producto!$D$6+200 -> 22870 | J20: =(E20-$D20)/E20 -> 0.21419518 | K20: =(F20-$D20)/F20 -> 0.20749893 | L20: =(G20-$D20)/G20 -> 0.20068758 | M20: =(H20-$D20)/H20 -> 0.19375813 | N20: =(I20-$D20)/I20 -> 0.18670748
A21: =Precios_Para_Comunicar!B18 -> Remera Clásica Mujer | B21: =Precios_Para_Comunicar!C18 -> Negra | C21: =Precios_Para_Comunicar!D18 -> tee_classic | D21: =Precios_Para_Comunicar!E18 -> 22670 | E21: =Resumen_por_Producto!$D$6+1000 -> 23670 | F21: =Resumen_por_Producto!$D$6+800 -> 23470 | G21: =Resumen_por_Producto!$D$6+600 -> 23270 | H21: =Resumen_por_Producto!$D$6+400 -> 23070 | I21: =Resumen_por_Producto!$D$6+200 -> 22870 | J21: =(E21-$D21)/E21 -> 0.042247571 | K21: =(F21-$D21)/F21 -> 0.034086067 | L21: =(G21-$D21)/G21 -> 0.025784272 | M21: =(H21-$D21)/H21 -> 0.017338535 | N21: =(I21-$D21)/I21 -> 0.0087450809
A22: =Precios_Para_Comunicar!B19 -> Remera Crop Mujer | B22: =Precios_Para_Comunicar!C19 -> Amarillo | C22: =Precios_Para_Comunicar!D19 -> crop | D22: =Precios_Para_Comunicar!E19 -> 18100 | E22: =Resumen_por_Producto!$D$7+1000 -> 19100 | F22: =Resumen_por_Producto!$D$7+800 -> 18900 | G22: =Resumen_por_Producto!$D$7+600 -> 18700 | H22: =Resumen_por_Producto!$D$7+400 -> 18500 | I22: =Resumen_por_Producto!$D$7+200 -> 18300 | J22: =(E22-$D22)/E22 -> 0.052356021 | K22: =(F22-$D22)/F22 -> 0.042328042 | L22: =(G22-$D22)/G22 -> 0.032085561 | M22: =(H22-$D22)/H22 -> 0.021621622 | N22: =(I22-$D22)/I22 -> 0.010928962
A23: =Precios_Para_Comunicar!B20 -> Remera Crop Mujer | B23: =Precios_Para_Comunicar!C20 -> Chocolate | C23: =Precios_Para_Comunicar!D20 -> crop | D23: =Precios_Para_Comunicar!E20 -> 18100 | E23: =Resumen_por_Producto!$D$7+1000 -> 19100 | F23: =Resumen_por_Producto!$D$7+800 -> 18900 | G23: =Resumen_por_Producto!$D$7+600 -> 18700 | H23: =Resumen_por_Producto!$D$7+400 -> 18500 | I23: =Resumen_por_Producto!$D$7+200 -> 18300 | J23: =(E23-$D23)/E23 -> 0.052356021 | K23: =(F23-$D23)/F23 -> 0.042328042 | L23: =(G23-$D23)/G23 -> 0.032085561 | M23: =(H23-$D23)/H23 -> 0.021621622 | N23: =(I23-$D23)/I23 -> 0.010928962
A24: =Precios_Para_Comunicar!B21 -> Remera Crop Mujer | B24: =Precios_Para_Comunicar!C21 -> Gris Melange | C24: =Precios_Para_Comunicar!D21 -> crop | D24: =Precios_Para_Comunicar!E21 -> 18100 | E24: =Resumen_por_Producto!$D$7+1000 -> 19100 | F24: =Resumen_por_Producto!$D$7+800 -> 18900 | G24: =Resumen_por_Producto!$D$7+600 -> 18700 | H24: =Resumen_por_Producto!$D$7+400 -> 18500 | I24: =Resumen_por_Producto!$D$7+200 -> 18300 | J24: =(E24-$D24)/E24 -> 0.052356021 | K24: =(F24-$D24)/F24 -> 0.042328042 | L24: =(G24-$D24)/G24 -> 0.032085561 | M24: =(H24-$D24)/H24 -> 0.021621622 | N24: =(I24-$D24)/I24 -> 0.010928962
A25: =Precios_Para_Comunicar!B22 -> Remera Crop Mujer | B25: =Precios_Para_Comunicar!C22 -> Negra | C25: =Precios_Para_Comunicar!D22 -> crop | D25: =Precios_Para_Comunicar!E22 -> 18100 | E25: =Resumen_por_Producto!$D$7+1000 -> 19100 | F25: =Resumen_por_Producto!$D$7+800 -> 18900 | G25: =Resumen_por_Producto!$D$7+600 -> 18700 | H25: =Resumen_por_Producto!$D$7+400 -> 18500 | I25: =Resumen_por_Producto!$D$7+200 -> 18300 | J25: =(E25-$D25)/E25 -> 0.052356021 | K25: =(F25-$D25)/F25 -> 0.042328042 | L25: =(G25-$D25)/G25 -> 0.032085561 | M25: =(H25-$D25)/H25 -> 0.021621622 | N25: =(I25-$D25)/I25 -> 0.010928962
A26: =Precios_Para_Comunicar!B23 -> Musculosa Bali | B26: =Precios_Para_Comunicar!C23 -> Blanca | C26: =Precios_Para_Comunicar!D23 -> tank | D26: =Precios_Para_Comunicar!E23 -> 18100 | E26: =Resumen_por_Producto!$D$8+1000 -> 19100 | F26: =Resumen_por_Producto!$D$8+800 -> 18900 | G26: =Resumen_por_Producto!$D$8+600 -> 18700 | H26: =Resumen_por_Producto!$D$8+400 -> 18500 | I26: =Resumen_por_Producto!$D$8+200 -> 18300 | J26: =(E26-$D26)/E26 -> 0.052356021 | K26: =(F26-$D26)/F26 -> 0.042328042 | L26: =(G26-$D26)/G26 -> 0.032085561 | M26: =(H26-$D26)/H26 -> 0.021621622 | N26: =(I26-$D26)/I26 -> 0.010928962
A27: =Precios_Para_Comunicar!B24 -> Musculosa Bali | B27: =Precios_Para_Comunicar!C24 -> Gris | C27: =Precios_Para_Comunicar!D24 -> tank | D27: =Precios_Para_Comunicar!E24 -> 18100 | E27: =Resumen_por_Producto!$D$8+1000 -> 19100 | F27: =Resumen_por_Producto!$D$8+800 -> 18900 | G27: =Resumen_por_Producto!$D$8+600 -> 18700 | H27: =Resumen_por_Producto!$D$8+400 -> 18500 | I27: =Resumen_por_Producto!$D$8+200 -> 18300 | J27: =(E27-$D27)/E27 -> 0.052356021 | K27: =(F27-$D27)/F27 -> 0.042328042 | L27: =(G27-$D27)/G27 -> 0.032085561 | M27: =(H27-$D27)/H27 -> 0.021621622 | N27: =(I27-$D27)/I27 -> 0.010928962
A28: =Precios_Para_Comunicar!B25 -> Musculosa Bali | B28: =Precios_Para_Comunicar!C25 -> Negra | C28: =Precios_Para_Comunicar!D25 -> tank | D28: =Precios_Para_Comunicar!E25 -> 18100 | E28: =Resumen_por_Producto!$D$8+1000 -> 19100 | F28: =Resumen_por_Producto!$D$8+800 -> 18900 | G28: =Resumen_por_Producto!$D$8+600 -> 18700 | H28: =Resumen_por_Producto!$D$8+400 -> 18500 | I28: =Resumen_por_Producto!$D$8+200 -> 18300 | J28: =(E28-$D28)/E28 -> 0.052356021 | K28: =(F28-$D28)/F28 -> 0.042328042 | L28: =(G28-$D28)/G28 -> 0.032085561 | M28: =(H28-$D28)/H28 -> 0.021621622 | N28: =(I28-$D28)/I28 -> 0.010928962

Sheet Detalle_SKU_Con_Margenes
A1: Nombre_Comercial | B1: Producto | C1: Color | D1: Talle | E1: Categoria | F1: Costo | G1: B2C | H1: Muestra | I1: Partner (1u) | J1: Starter (5-9u) | K1: Pro (10-20u) | L1: Drop (30-99u) | M1: Bulk (100+u) | N1: $_Partner | O1: %_Partner | P1: $_Starter | Q1: %_Starter | R1: $_Pro | S1: %_Pro | T1: $_Drop | U1: %_Drop | V1: $_Bulk | W1: %_Bulk
A2: Berlin | B2: Buzo Cuello Redondo | C2: Blanco | D2: XS | E2: crewneck | F2: ='Precios Tab Dreamfull-sheets'!$G$2 -> 24100 | G2: 43000 | H2: 32200 | I2: 32200 | J2: 31200 | K2: 30200 | L2: 29200 | M2: 28200 | N2: =I2-$F2 -> 8100 | O2: =N2/I2 -> 0.2515528 | P2: =J2-$F2 -> 7100 | Q2: =P2/J2 -> 0.2275641 | R2: =K2-$F2 -> 6100 | S2: =R2/K2 -> 0.20198675 | T2: =L2-$F2 -> 5100 | U2: =T2/L2 -> 0.17465753 | V2: =M2-$F2 -> 4100 | W2: =V2/M2 -> 0.14539007
A3: Berlin | B3: Buzo Cuello Redondo | C3: Blanco | D3: S | E3: crewneck | F3: ='Precios Tab Dreamfull-sheets'!$G$2 -> 24100 | G3: 43000 | H3: 32200 | I3: 32200 | J3: 31200 | K3: 30200 | L3: 29200 | M3: 28200 | N3: =I3-$F3 -> 8100 | O3: =N3/I3 -> 0.2515528 | P3: =J3-$F3 -> 7100 | Q3: =P3/J3 -> 0.2275641 | R3: =K3-$F3 -> 6100 | S3: =R3/K3 -> 0.20198675 | T3: =L3-$F3 -> 5100 | U3: =T3/L3 -> 0.17465753 | V3: =M3-$F3 -> 4100 | W3: =V3/M3 -> 0.14539007
A4: Berlin | B4: Buzo Cuello Redondo | C4: Blanco | D4: M | E4: crewneck | F4: ='Precios Tab Dreamfull-sheets'!$G$2 -> 24100 | G4: 43000 | H4: 32200 | I4: 32200 | J4: 31200 | K4: 30200 | L4: 29200 | M4: 28200 | N4: =I4-$F4 -> 8100 | O4: =N4/I4 -> 0.2515528 | P4: =J4-$F4 -> 7100 | Q4: =P4/J4 -> 0.2275641 | R4: =K4-$F4 -> 6100 | S4: =R4/K4 -> 0.20198675 | T4: =L4-$F4 -> 5100 | U4: =T4/L4 -> 0.17465753 | V4: =M4-$F4 -> 4100 | W4: =V4/M4 -> 0.14539007
A5: Berlin | B5: Buzo Cuello Redondo | C5: Blanco | D5: L | E5: crewneck | F5: ='Precios Tab Dreamfull-sheets'!$G$2 -> 24100 | G5: 43000 | H5: 32200 | I5: 32200 | J5: 31200 | K5: 30200 | L5: 29200 | M5: 28200 | N5: =I5-$F5 -> 8100 | O5: =N5/I5 -> 0.2515528 | P5: =J5-$F5 -> 7100 | Q5: =P5/J5 -> 0.2275641 | R5: =K5-$F5 -> 6100 | S5: =R5/K5 -> 0.20198675 | T5: =L5-$F5 -> 5100 | U5: =T5/L5 -> 0.17465753 | V5: =M5-$F5 -> 4100 | W5: =V5/M5 -> 0.14539007
A6: Berlin | B6: Buzo Cuello Redondo | C6: Blanco | D6: XL | E6: crewneck | F6: ='Precios Tab Dreamfull-sheets'!$G$2 -> 24100 | G6: 43000 | H6: 32200 | I6: 32200 | J6: 31200 | K6: 30200 | L6: 29200 | M6: 28200 | N6: =I6-$F6 -> 8100 | O6: =N6/I6 -> 0.2515528 | P6: =J6-$F6 -> 7100 | Q6: =P6/J6 -> 0.2275641 | R6: =K6-$F6 -> 6100 | S6: =R6/K6 -> 0.20198675 | T6: =L6-$F6 -> 5100 | U6: =T6/L6 -> 0.17465753 | V6: =M6-$F6 -> 4100 | W6: =V6/M6 -> 0.14539007
A7: Berlin | B7: Buzo Cuello Redondo | C7: Blanco | D7: 2XL | E7: crewneck | F7: ='Precios Tab Dreamfull-sheets'!$G$2 -> 24100 | G7: 43000 | H7: 32200 | I7: 32200 | J7: 31200 | K7: 30200 | L7: 29200 | M7: 28200 | N7: =I7-$F7 -> 8100 | O7: =N7/I7 -> 0.2515528 | P7: =J7-$F7 -> 7100 | Q7: =P7/J7 -> 0.2275641 | R7: =K7-$F7 -> 6100 | S7: =R7/K7 -> 0.20198675 | T7: =L7-$F7 -> 5100 | U7: =T7/L7 -> 0.17465753 | V7: =M7-$F7 -> 4100 | W7: =V7/M7 -> 0.14539007
A8: Berlin | B8: Buzo Cuello Redondo | C8: Negro | D8: XS | E8: crewneck | F8: ='Precios Tab Dreamfull-sheets'!$G$3 -> 28170 | G8: 43000 | H8: 32200 | I8: 32200 | J8: 31200 | K8: 30200 | L8: 29200 | M8: 28200 | N8: =I8-$F8 -> 4030 | O8: =N8/I8 -> 0.12515528 | P8: =J8-$F8 -> 3030 | Q8: =P8/J8 -> 0.097115385 | R8: =K8-$F8 -> 2030 | S8: =R8/K8 -> 0.067218543 | T8: =L8-$F8 -> 1030 | U8: =T8/L8 -> 0.035273973 | V8: =M8-$F8 -> 30 | W8: =V8/M8 -> 0.0010638298
A9: Berlin | B9: Buzo Cuello Redondo | C9: Negro | D9: S | E9: crewneck | F9: ='Precios Tab Dreamfull-sheets'!$G$3 -> 28170 | G9: 43000 | H9: 32200 | I9: 32200 | J9: 31200 | K9: 30200 | L9: 29200 | M9: 28200 | N9: =I9-$F9 -> 4030 | O9: =N9/I9 -> 0.12515528 | P9: =J9-$F9 -> 3030 | Q9: =P9/J9 -> 0.097115385 | R9: =K9-$F9 -> 2030 | S9: =R9/K9 -> 0.067218543 | T9: =L9-$F9 -> 1030 | U9: =T9/L9 -> 0.035273973 | V9: =M9-$F9 -> 30 | W9: =V9/M9 -> 0.0010638298
A10: Berlin | B10: Buzo Cuello Redondo | C10: Negro | D10: M | E10: crewneck | F10: ='Precios Tab Dreamfull-sheets'!$G$3 -> 28170 | G10: 43000 | H10: 32200 | I10: 32200 | J10: 31200 | K10: 30200 | L10: 29200 | M10: 28200 | N10: =I10-$F10 -> 4030 | O10: =N10/I10 -> 0.12515528 | P10: =J10-$F10 -> 3030 | Q10: =P10/J10 -> 0.097115385 | R10: =K10-$F10 -> 2030 | S10: =R10/K10 -> 0.067218543 | T10: =L10-$F10 -> 1030 | U10: =T10/L10 -> 0.035273973 | V10: =M10-$F10 -> 30 | W10: =V10/M10 -> 0.0010638298
A11: Berlin | B11: Buzo Cuello Redondo | C11: Negro | D11: L | E11: crewneck | F11: ='Precios Tab Dreamfull-sheets'!$G$3 -> 28170 | G11: 43000 | H11: 32200 | I11: 32200 | J11: 31200 | K11: 30200 | L11: 29200 | M11: 28200 | N11: =I11-$F11 -> 4030 | O11: =N11/I11 -> 0.12515528 | P11: =J11-$F11 -> 3030 | Q11: =P11/J11 -> 0.097115385 | R11: =K11-$F11 -> 2030 | S11: =R11/K11 -> 0.067218543 | T11: =L11-$F11 -> 1030 | U11: =T11/L11 -> 0.035273973 | V11: =M11-$F11 -> 30 | W11: =V11/M11 -> 0.0010638298
A12: Berlin | B12: Buzo Cuello Redondo | C12: Negro | D12: XL | E12: crewneck | F12: ='Precios Tab Dreamfull-sheets'!$G$3 -> 28170 | G12: 43000 | H12: 32200 | I12: 32200 | J12: 31200 | K12: 30200 | L12: 29200 | M12: 28200 | N12: =I12-$F12 -> 4030 | O12: =N12/I12 -> 0.12515528 | P12: =J12-$F12 -> 3030 | Q12: =P12/J12 -> 0.097115385 | R12: =K12-$F12 -> 2030 | S12: =R12/K12 -> 0.067218543 | T12: =L12-$F12 -> 1030 | U12: =T12/L12 -> 0.035273973 | V12: =M12-$F12 -> 30 | W12: =V12/M12 -> 0.0010638298
A13: Berlin | B13: Buzo Cuello Redondo | C13: Negro | D13: 2XL | E13: crewneck | F13: ='Precios Tab Dreamfull-sheets'!$G$3 -> 28170 | G13: 43000 | H13: 32200 | I13: 32200 | J13: 31200 | K13: 30200 | L13: 29200 | M13: 28200 | N13: =I13-$F13 -> 4030 | O13: =N13/I13 -> 0.12515528 | P13: =J13-$F13 -> 3030 | Q13: =P13/J13 -> 0.097115385 | R13: =K13-$F13 -> 2030 | S13: =R13/K13 -> 0.067218543 | T13: =L13-$F13 -> 1030 | U13: =T13/L13 -> 0.035273973 | V13: =M13-$F13 -> 30 | W13: =V13/M13 -> 0.0010638298
A14: Berlin | B14: Buzo Cuello Redondo | C14: Stone Wash | D14: XS | E14: crewneck | F14: ='Precios Tab Dreamfull-sheets'!$G$4 -> 28170 | G14: 43000 | H14: 32200 | I14: 32200 | J14: 31200 | K14: 30200 | L14: 29200 | M14: 28200 | N14: =I14-$F14 -> 4030 | O14: =N14/I14 -> 0.12515528 | P14: =J14-$F14 -> 3030 | Q14: =P14/J14 -> 0.097115385 | R14: =K14-$F14 -> 2030 | S14: =R14/K14 -> 0.067218543 | T14: =L14-$F14 -> 1030 | U14: =T14/L14 -> 0.035273973 | V14: =M14-$F14 -> 30 | W14: =V14/M14 -> 0.0010638298
A15: Berlin | B15: Buzo Cuello Redondo | C15: Stone Wash | D15: S | E15: crewneck | F15: ='Precios Tab Dreamfull-sheets'!$G$4 -> 28170 | G15: 43000 | H15: 32200 | I15: 32200 | J15: 31200 | K15: 30200 | L15: 29200 | M15: 28200 | N15: =I15-$F15 -> 4030 | O15: =N15/I15 -> 0.12515528 | P15: =J15-$F15 -> 3030 | Q15: =P15/J15 -> 0.097115385 | R15: =K15-$F15 -> 2030 | S15: =R15/K15 -> 0.067218543 | T15: =L15-$F15 -> 1030 | U15: =T15/L15 -> 0.035273973 | V15: =M15-$F15 -> 30 | W15: =V15/M15 -> 0.0010638298
A16: Berlin | B16: Buzo Cuello Redondo | C16: Stone Wash | D16: M | E16: crewneck | F16: ='Precios Tab Dreamfull-sheets'!$G$4 -> 28170 | G16: 43000 | H16: 32200 | I16: 32200 | J16: 31200 | K16: 30200 | L16: 29200 | M16: 28200 | N16: =I16-$F16 -> 4030 | O16: =N16/I16 -> 0.12515528 | P16: =J16-$F16 -> 3030 | Q16: =P16/J16 -> 0.097115385 | R16: =K16-$F16 -> 2030 | S16: =R16/K16 -> 0.067218543 | T16: =L16-$F16 -> 1030 | U16: =T16/L16 -> 0.035273973 | V16: =M16-$F16 -> 30 | W16: =V16/M16 -> 0.0010638298
A17: Berlin | B17: Buzo Cuello Redondo | C17: Stone Wash | D17: L | E17: crewneck | F17: ='Precios Tab Dreamfull-sheets'!$G$4 -> 28170 | G17: 43000 | H17: 32200 | I17: 32200 | J17: 31200 | K17: 30200 | L17: 29200 | M17: 28200 | N17: =I17-$F17 -> 4030 | O17: =N17/I17 -> 0.12515528 | P17: =J17-$F17 -> 3030 | Q17: =P17/J17 -> 0.097115385 | R17: =K17-$F17 -> 2030 | S17: =R17/K17 -> 0.067218543 | T17: =L17-$F17 -> 1030 | U17: =T17/L17 -> 0.035273973 | V17: =M17-$F17 -> 30 | W17: =V17/M17 -> 0.0010638298
A18: Berlin | B18: Buzo Cuello Redondo | C18: Stone Wash | D18: XL | E18: crewneck | F18: ='Precios Tab Dreamfull-sheets'!$G$4 -> 28170 | G18: 43000 | H18: 32200 | I18: 32200 | J18: 31200 | K18: 30200 | L18: 29200 | M18: 28200 | N18: =I18-$F18 -> 4030 | O18: =N18/I18 -> 0.12515528 | P18: =J18-$F18 -> 3030 | Q18: =P18/J18 -> 0.097115385 | R18: =K18-$F18 -> 2030 | S18: =R18/K18 -> 0.067218543 | T18: =L18-$F18 -> 1030 | U18: =T18/L18 -> 0.035273973 | V18: =M18-$F18 -> 30 | W18: =V18/M18 -> 0.0010638298
A19: Berlin | B19: Buzo Cuello Redondo | C19: Stone Wash | D19: 2XL | E19: crewneck | F19: ='Precios Tab Dreamfull-sheets'!$G$4 -> 28170 | G19: 43000 | H19: 32200 | I19: 32200 | J19: 31200 | K19: 30200 | L19: 29200 | M19: 28200 | N19: =I19-$F19 -> 4030 | O19: =N19/I19 -> 0.12515528 | P19: =J19-$F19 -> 3030 | Q19: =P19/J19 -> 0.097115385 | R19: =K19-$F19 -> 2030 | S19: =R19/K19 -> 0.067218543 | T19: =L19-$F19 -> 1030 | U19: =T19/L19 -> 0.035273973 | V19: =M19-$F19 -> 30 | W19: =V19/M19 -> 0.0010638298
A20: Boston | B20: Buzo Hoodie Unisex | C20: Blanco | D20: XS | E20: hoodie | F20: ='Precios Tab Dreamfull-sheets'!$G$9 -> 25100 | G20: 55000 | H20: 38700 | I20: 38700 | J20: 36600 | K20: 34500 | L20: 32400 | M20: 30300 | N20: =I20-$F20 -> 13600 | O20: =N20/I20 -> 0.35142119 | P20: =J20-$F20 -> 11500 | Q20: =P20/J20 -> 0.31420765 | R20: =K20-$F20 -> 9400 | S20: =R20/K20 -> 0.27246377 | T20: =L20-$F20 -> 7300 | U20: =T20/L20 -> 0.22530864 | V20: =M20-$F20 -> 5200 | W20: =V20/M20 -> 0.17161716
A21: Boston | B21: Buzo Hoodie Unisex | C21: Blanco | D21: S | E21: hoodie | F21: ='Precios Tab Dreamfull-sheets'!$G$9 -> 25100 | G21: 55000 | H21: 38700 | I21: 38700 | J21: 36600 | K21: 34500 | L21: 32400 | M21: 30300 | N21: =I21-$F21 -> 13600 | O21: =N21/I21 -> 0.35142119 | P21: =J21-$F21 -> 11500 | Q21: =P21/J21 -> 0.31420765 | R21: =K21-$F21 -> 9400 | S21: =R21/K21 -> 0.27246377 | T21: =L21-$F21 -> 7300 | U21: =T21/L21 -> 0.22530864 | V21: =M21-$F21 -> 5200 | W21: =V21/M21 -> 0.17161716
A22: Boston | B22: Buzo Hoodie Unisex | C22: Blanco | D22: M | E22: hoodie | F22: ='Precios Tab Dreamfull-sheets'!$G$9 -> 25100 | G22: 55000 | H22: 38700 | I22: 38700 | J22: 36600 | K22: 34500 | L22: 32400 | M22: 30300 | N22: =I22-$F22 -> 13600 | O22: =N22/I22 -> 0.35142119 | P22: =J22-$F22 -> 11500 | Q22: =P22/J22 -> 0.31420765 | R22: =K22-$F22 -> 9400 | S22: =R22/K22 -> 0.27246377 | T22: =L22-$F22 -> 7300 | U22: =T22/L22 -> 0.22530864 | V22: =M22-$F22 -> 5200 | W22: =V22/M22 -> 0.17161716
A23: Boston | B23: Buzo Hoodie Unisex | C23: Blanco | D23: L | E23: hoodie | F23: ='Precios Tab Dreamfull-sheets'!$G$9 -> 25100 | G23: 55000 | H23: 38700 | I23: 38700 | J23: 36600 | K23: 34500 | L23: 32400 | M23: 30300 | N23: =I23-$F23 -> 13600 | O23: =N23/I23 -> 0.35142119 | P23: =J23-$F23 -> 11500 | Q23: =P23/J23 -> 0.31420765 | R23: =K23-$F23 -> 9400 | S23: =R23/K23 -> 0.27246377 | T23: =L23-$F23 -> 7300 | U23: =T23/L23 -> 0.22530864 | V23: =M23-$F23 -> 5200 | W23: =V23/M23 -> 0.17161716
A24: Boston | B24: Buzo Hoodie Unisex | C24: Blanco | D24: XL | E24: hoodie | F24: ='Precios Tab Dreamfull-sheets'!$G$9 -> 25100 | G24: 55000 | H24: 38700 | I24: 38700 | J24: 36600 | K24: 34500 | L24: 32400 | M24: 30300 | N24: =I24-$F24 -> 13600 | O24: =N24/I24 -> 0.35142119 | P24: =J24-$F24 -> 11500 | Q24: =P24/J24 -> 0.31420765 | R24: =K24-$F24 -> 9400 | S24: =R24/K24 -> 0.27246377 | T24: =L24-$F24 -> 7300 | U24: =T24/L24 -> 0.22530864 | V24: =M24-$F24 -> 5200 | W24: =V24/M24 -> 0.17161716
A25: Boston | B25: Buzo Hoodie Unisex | C25: Blanco | D25: 2XL | E25: hoodie | F25: ='Precios Tab Dreamfull-sheets'!$G$9 -> 25100 | G25: 55000 | H25: 38700 | I25: 38700 | J25: 36600 | K25: 34500 | L25: 32400 | M25: 30300 | N25: =I25-$F25 -> 13600 | O25: =N25/I25 -> 0.35142119 | P25: =J25-$F25 -> 11500 | Q25: =P25/J25 -> 0.31420765 | R25: =K25-$F25 -> 9400 | S25: =R25/K25 -> 0.27246377 | T25: =L25-$F25 -> 7300 | U25: =T25/L25 -> 0.22530864 | V25: =M25-$F25 -> 5200 | W25: =V25/M25 -> 0.17161716
A26: Boston | B26: Buzo Hoodie Unisex | C26: Negro | D26: XS | E26: hoodie | F26: ='Precios Tab Dreamfull-sheets'!$G$10 -> 29170 | G26: 55000 | H26: 38700 | I26: 38700 | J26: 36600 | K26: 34500 | L26: 32400 | M26: 30300 | N26: =I26-$F26 -> 9530 | O26: =N26/I26 -> 0.24625323 | P26: =J26-$F26 -> 7430 | Q26: =P26/J26 -> 0.20300546 | R26: =K26-$F26 -> 5330 | S26: =R26/K26 -> 0.15449275 | T26: =L26-$F26 -> 3230 | U26: =T26/L26 -> 0.099691358 | V26: =M26-$F26 -> 1130 | W26: =V26/M26 -> 0.037293729
A27: Boston | B27: Buzo Hoodie Unisex | C27: Negro | D27: S | E27: hoodie | F27: ='Precios Tab Dreamfull-sheets'!$G$10 -> 29170 | G27: 55000 | H27: 38700 | I27: 38700 | J27: 36600 | K27: 34500 | L27: 32400 | M27: 30300 | N27: =I27-$F27 -> 9530 | O27: =N27/I27 -> 0.24625323 | P27: =J27-$F27 -> 7430 | Q27: =P27/J27 -> 0.20300546 | R27: =K27-$F27 -> 5330 | S27: =R27/K27 -> 0.15449275 | T27: =L27-$F27 -> 3230 | U27: =T27/L27 -> 0.099691358 | V27: =M27-$F27 -> 1130 | W27: =V27/M27 -> 0.037293729
A28: Boston | B28: Buzo Hoodie Unisex | C28: Negro | D28: M | E28: hoodie | F28: ='Precios Tab Dreamfull-sheets'!$G$10 -> 29170 | G28: 55000 | H28: 38700 | I28: 38700 | J28: 36600 | K28: 34500 | L28: 32400 | M28: 30300 | N28: =I28-$F28 -> 9530 | O28: =N28/I28 -> 0.24625323 | P28: =J28-$F28 -> 7430 | Q28: =P28/J28 -> 0.20300546 | R28: =K28-$F28 -> 5330 | S28: =R28/K28 -> 0.15449275 | T28: =L28-$F28 -> 3230 | U28: =T28/L28 -> 0.099691358 | V28: =M28-$F28 -> 1130 | W28: =V28/M28 -> 0.037293729
A29: Boston | B29: Buzo Hoodie Unisex | C29: Negro | D29: L | E29: hoodie | F29: ='Precios Tab Dreamfull-sheets'!$G$10 -> 29170 | G29: 55000 | H29: 38700 | I29: 38700 | J29: 36600 | K29: 34500 | L29: 32400 | M29: 30300 | N29: =I29-$F29 -> 9530 | O29: =N29/I29 -> 0.24625323 | P29: =J29-$F29 -> 7430 | Q29: =P29/J29 -> 0.20300546 | R29: =K29-$F29 -> 5330 | S29: =R29/K29 -> 0.15449275 | T29: =L29-$F29 -> 3230 | U29: =T29/L29 -> 0.099691358 | V29: =M29-$F29 -> 1130 | W29: =V29/M29 -> 0.037293729
A30: Boston | B30: Buzo Hoodie Unisex | C30: Negro | D30: XL | E30: hoodie | F30: ='Precios Tab Dreamfull-sheets'!$G$10 -> 29170 | G30: 55000 | H30: 38700 | I30: 38700 | J30: 36600 | K30: 34500 | L30: 32400 | M30: 30300 | N30: =I30-$F30 -> 9530 | O30: =N30/I30 -> 0.24625323 | P30: =J30-$F30 -> 7430 | Q30: =P30/J30 -> 0.20300546 | R30: =K30-$F30 -> 5330 | S30: =R30/K30 -> 0.15449275 | T30: =L30-$F30 -> 3230 | U30: =T30/L30 -> 0.099691358 | V30: =M30-$F30 -> 1130 | W30: =V30/M30 -> 0.037293729
A31: Boston | B31: Buzo Hoodie Unisex | C31: Negro | D31: 2XL | E31: hoodie | F31: ='Precios Tab Dreamfull-sheets'!$G$10 -> 29170 | G31: 55000 | H31: 38700 | I31: 38700 | J31: 36600 | K31: 34500 | L31: 32400 | M31: 30300 | N31: =I31-$F31 -> 9530 | O31: =N31/I31 -> 0.24625323 | P31: =J31-$F31 -> 7430 | Q31: =P31/J31 -> 0.20300546 | R31: =K31-$F31 -> 5330 | S31: =R31/K31 -> 0.15449275 | T31: =L31-$F31 -> 3230 | U31: =T31/L31 -> 0.099691358 | V31: =M31-$F31 -> 1130 | W31: =V31/M31 -> 0.037293729
A32: Boston | B32: Buzo Hoodie Unisex | C32: Stone Wash | D32: XS | E32: hoodie | F32: ='Precios Tab Dreamfull-sheets'!$G$11 -> 30170 | G32: 55000 | H32: 38700 | I32: 38700 | J32: 36600 | K32: 34500 | L32: 32400 | M32: 30300 | N32: =I32-$F32 -> 8530 | O32: =N32/I32 -> 0.22041344 | P32: =J32-$F32 -> 6430 | Q32: =P32/J32 -> 0.17568306 | R32: =K32-$F32 -> 4330 | S32: =R32/K32 -> 0.12550725 | T32: =L32-$F32 -> 2230 | U32: =T32/L32 -> 0.06882716 | V32: =M32-$F32 -> 130 | W32: =V32/M32 -> 0.004290429
A33: Boston | B33: Buzo Hoodie Unisex | C33: Stone Wash | D33: S | E33: hoodie | F33: ='Precios Tab Dreamfull-sheets'!$G$11 -> 30170 | G33: 55000 | H33: 38700 | I33: 38700 | J33: 36600 | K33: 34500 | L33: 32400 | M33: 30300 | N33: =I33-$F33 -> 8530 | O33: =N33/I33 -> 0.22041344 | P33: =J33-$F33 -> 6430 | Q33: =P33/J33 -> 0.17568306 | R33: =K33-$F33 -> 4330 | S33: =R33/K33 -> 0.12550725 | T33: =L33-$F33 -> 2230 | U33: =T33/L33 -> 0.06882716 | V33: =M33-$F33 -> 130 | W33: =V33/M33 -> 0.004290429
A34: Boston | B34: Buzo Hoodie Unisex | C34: Stone Wash | D34: M | E34: hoodie | F34: ='Precios Tab Dreamfull-sheets'!$G$11 -> 30170 | G34: 55000 | H34: 38700 | I34: 38700 | J34: 36600 | K34: 34500 | L34: 32400 | M34: 30300 | N34: =I34-$F34 -> 8530 | O34: =N34/I34 -> 0.22041344 | P34: =J34-$F34 -> 6430 | Q34: =P34/J34 -> 0.17568306 | R34: =K34-$F34 -> 4330 | S34: =R34/K34 -> 0.12550725 | T34: =L34-$F34 -> 2230 | U34: =T34/L34 -> 0.06882716 | V34: =M34-$F34 -> 130 | W34: =V34/M34 -> 0.004290429
A35: Boston | B35: Buzo Hoodie Unisex | C35: Stone Wash | D35: L | E35: hoodie | F35: ='Precios Tab Dreamfull-sheets'!$G$11 -> 30170 | G35: 55000 | H35: 38700 | I35: 38700 | J35: 36600 | K35: 34500 | L35: 32400 | M35: 30300 | N35: =I35-$F35 -> 8530 | O35: =N35/I35 -> 0.22041344 | P35: =J35-$F35 -> 6430 | Q35: =P35/J35 -> 0.17568306 | R35: =K35-$F35 -> 4330 | S35: =R35/K35 -> 0.12550725 | T35: =L35-$F35 -> 2230 | U35: =T35/L35 -> 0.06882716 | V35: =M35-$F35 -> 130 | W35: =V35/M35 -> 0.004290429
A36: Boston | B36: Buzo Hoodie Unisex | C36: Stone Wash | D36: XL | E36: hoodie | F36: ='Precios Tab Dreamfull-sheets'!$G$11 -> 30170 | G36: 55000 | H36: 38700 | I36: 38700 | J36: 36600 | K36: 34500 | L36: 32400 | M36: 30300 | N36: =I36-$F36 -> 8530 | O36: =N36/I36 -> 0.22041344 | P36: =J36-$F36 -> 6430 | Q36: =P36/J36 -> 0.17568306 | R36: =K36-$F36 -> 4330 | S36: =R36/K36 -> 0.12550725 | T36: =L36-$F36 -> 2230 | U36: =T36/L36 -> 0.06882716 | V36: =M36-$F36 -> 130 | W36: =V36/M36 -> 0.004290429
A37: Boston | B37: Buzo Hoodie Unisex | C37: Stone Wash | D37: 2XL | E37: hoodie | F37: ='Precios Tab Dreamfull-sheets'!$G$11 -> 30170 | G37: 55000 | H37: 38700 | I37: 38700 | J37: 36600 | K37: 34500 | L37: 32400 | M37: 30300 | N37: =I37-$F37 -> 8530 | O37: =N37/I37 -> 0.22041344 | P37: =J37-$F37 -> 6430 | Q37: =P37/J37 -> 0.17568306 | R37: =K37-$F37 -> 4330 | S37: =R37/K37 -> 0.12550725 | T37: =L37-$F37 -> 2230 | U37: =T37/L37 -> 0.06882716 | V37: =M37-$F37 -> 130 | W37: =V37/M37 -> 0.004290429
A38: Boston | B38: Buzo Hoodie Unisex | C38: Caramel | D38: S | E38: hoodie | F38: ='Precios Tab Dreamfull-sheets'!$G$10 -> 29170 | G38: 55000 | H38: 38700 | I38: 38700 | J38: 36600 | K38: 34500 | L38: 32400 | M38: 30300 | N38: =I38-$F38 -> 9530 | O38: =N38/I38 -> 0.24625323 | P38: =J38-$F38 -> 7430 | Q38: =P38/J38 -> 0.20300546 | R38: =K38-$F38 -> 5330 | S38: =R38/K38 -> 0.15449275 | T38: =L38-$F38 -> 3230 | U38: =T38/L38 -> 0.099691358 | V38: =M38-$F38 -> 1130 | W38: =V38/M38 -> 0.037293729
A39: Boston | B39: Buzo Hoodie Unisex | C39: Caramel | D39: M | E39: hoodie | F39: ='Precios Tab Dreamfull-sheets'!$G$10 -> 29170 | G39: 55000 | H39: 38700 | I39: 38700 | J39: 36600 | K39: 34500 | L39: 32400 | M39: 30300 | N39: =I39-$F39 -> 9530 | O39: =N39/I39 -> 0.24625323 | P39: =J39-$F39 -> 7430 | Q39: =P39/J39 -> 0.20300546 | R39: =K39-$F39 -> 5330 | S39: =R39/K39 -> 0.15449275 | T39: =L39-$F39 -> 3230 | U39: =T39/L39 -> 0.099691358 | V39: =M39-$F39 -> 1130 | W39: =V39/M39 -> 0.037293729
A40: Boston | B40: Buzo Hoodie Unisex | C40: Caramel | D40: L | E40: hoodie | F40: ='Precios Tab Dreamfull-sheets'!$G$10 -> 29170 | G40: 55000 | H40: 38700 | I40: 38700 | J40: 36600 | K40: 34500 | L40: 32400 | M40: 30300 | N40: =I40-$F40 -> 9530 | O40: =N40/I40 -> 0.24625323 | P40: =J40-$F40 -> 7430 | Q40: =P40/J40 -> 0.20300546 | R40: =K40-$F40 -> 5330 | S40: =R40/K40 -> 0.15449275 | T40: =L40-$F40 -> 3230 | U40: =T40/L40 -> 0.099691358 | V40: =M40-$F40 -> 1130 | W40: =V40/M40 -> 0.037293729
...

Sheet Resumen_por_Producto
A1: Nombre_Comercial | B1: Producto | C1: Costo_Min | D1: Costo_Max | E1: B2C | F1: Muestra | G1: Partner (1u) | H1: Starter (5-9u) | I1: Pro (10-20u) | J1: Drop (30-99u) | K1: Bulk (100+u) | L1: Margen%_Partner_min | M1: Margen%_Bulk_max | N1: Tier_Starter_Cant | O1: Tier_Pro_Cant | P1: Tier_Drop_Cant | Q1: Tier_Bulk_Cant
B2: Buzo Cuello Redondo | C2: =MIN(Precios_Para_Comunicar!E2:E4) -> 24100 | D2: =MAX(Precios_Para_Comunicar!E2:E4) -> 28170 | E2: 43000 | F2: 32200 | G2: =MIN(Precios_Para_Comunicar!H2:H4) -> 32200 | H2: =MIN(Precios_Para_Comunicar!I2:I4) -> 31200 | I2: =MIN(Precios_Para_Comunicar!J2:J4) -> 30200 | J2: =MIN(Precios_Para_Comunicar!K2:K4) -> 29200 | K2: =MIN(Precios_Para_Comunicar!L2:L4) -> 28200 | L2: =MIN(Precios_Para_Comunicar!M2:M4) -> 0.12515528 | M2: =MAX(Precios_Para_Comunicar!Q2:Q4) -> 0.14539007 | N2: 5-9 u | O2: 10-20 u | P2: 30-99 u | Q2: 100+ u
B3: Buzo Hoodie Unisex | C3: =MIN(Precios_Para_Comunicar!E5:E10) -> 25100 | D3: =MAX(Precios_Para_Comunicar!E5:E10) -> 30170 | E3: 55000 | F3: 38700 | G3: =MIN(Precios_Para_Comunicar!H5:H10) -> 38700 | H3: =MIN(Precios_Para_Comunicar!I5:I10) -> 36600 | I3: =MIN(Precios_Para_Comunicar!J5:J10) -> 34500 | J3: =MIN(Precios_Para_Comunicar!K5:K10) -> 32400 | K3: =MIN(Precios_Para_Comunicar!L5:L10) -> 30300 | L3: =MIN(Precios_Para_Comunicar!M5:M10) -> 0.22041344 | M3: =MAX(Precios_Para_Comunicar!Q5:Q10) -> 0.17161716 | N3: 5-9 u | O3: 10-20 u | P3: 30-99 u | Q3: 100+ u
B4: Aura Oversize T-Shirt | C4: =MIN(Precios_Para_Comunicar!E11:E14) -> 19000 | D4: =MAX(Precios_Para_Comunicar!E11:E14) -> 23470 | E4: 31000 | F4: 25400 | G4: =MIN(Precios_Para_Comunicar!H11:H14) -> 26600 | H4: =MIN(Precios_Para_Comunicar!I11:I14) -> 25900 | I4: =MIN(Precios_Para_Comunicar!J11:J14) -> 25100 | J4: =MIN(Precios_Para_Comunicar!K11:K14) -> 24300 | K4: =MIN(Precios_Para_Comunicar!L11:L14) -> 23600 | L4: =MIN(Precios_Para_Comunicar!M11:M14) -> 0.11766917 | M4: =MAX(Precios_Para_Comunicar!Q11:Q14) -> 0.19491525 | N4: 5-9 u | O4: 10-20 u | P4: 30-99 u | Q4: 100+ u
B5: Aldea Classic Fit T-Shirt | C5: =MIN(Precios_Para_Comunicar!E15:E16) -> 18600 | D5: =MAX(Precios_Para_Comunicar!E15:E16) -> 22670 | E5: 28600 | F5: 25700 | G5: =MIN(Precios_Para_Comunicar!H15:H16) -> 25800 | H5: =MIN(Precios_Para_Comunicar!I15:I16) -> 25100 | I5: =MIN(Precios_Para_Comunicar!J15:J16) -> 24400 | J5: =MIN(Precios_Para_Comunicar!K15:K16) -> 23800 | K5: =MIN(Precios_Para_Comunicar!L15:L16) -> 23600 | L5: =MIN(Precios_Para_Comunicar!M15:M16) -> 0.12131783 | M5: =MAX(Precios_Para_Comunicar!Q15:Q16) -> 0.21186441 | N5: 5-9 u | O5: 10-20 u | P5: 30-99 u | Q5: 100+ u
B6: Remera Clásica Mujer | C6: =MIN(Precios_Para_Comunicar!E17:E18) -> 18600 | D6: =MAX(Precios_Para_Comunicar!E17:E18) -> 22670 | E6: 28600 | F6: 25700 | G6: =MIN(Precios_Para_Comunicar!H17:H18) -> 25800 | H6: =MIN(Precios_Para_Comunicar!I17:I18) -> 25100 | I6: =MIN(Precios_Para_Comunicar!J17:J18) -> 24400 | J6: =MIN(Precios_Para_Comunicar!K17:K18) -> 23800 | K6: =MIN(Precios_Para_Comunicar!L17:L18) -> 23600 | L6: =MIN(Precios_Para_Comunicar!M17:M18) -> 0.12131783 | M6: =MAX(Precios_Para_Comunicar!Q17:Q18) -> 0.21186441 | N6: 5-9 u | O6: 10-20 u | P6: 30-99 u | Q6: 100+ u
B7: Remera Crop Mujer | C7: =MIN(Precios_Para_Comunicar!E19:E22) -> 18100 | D7: =MAX(Precios_Para_Comunicar!E19:E22) -> 18100 | E7: 23500 | F7: 19300 | G7: =MIN(Precios_Para_Comunicar!H19:H22) -> 20800 | H7: =MIN(Precios_Para_Comunicar!I19:I22) -> 20300 | I7: =MIN(Precios_Para_Comunicar!J19:J22) -> 19800 | J7: =MIN(Precios_Para_Comunicar!K19:K22) -> 19300 | K7: =MIN(Precios_Para_Comunicar!L19:L22) -> 18900 | L7: =MIN(Precios_Para_Comunicar!M19:M22) -> 0.12980769 | M7: =MAX(Precios_Para_Comunicar!Q19:Q22) -> 0.042328042 | N7: 5-9 u | O7: 10-20 u | P7: 30-99 u | Q7: 100+ u
B8: Musculosa Bali | C8: =MIN(Precios_Para_Comunicar!E23:E25) -> 18100 | D8: =MAX(Precios_Para_Comunicar!E23:E25) -> 18100 | E8: 21800 | F8: 17400 | G8: =MIN(Precios_Para_Comunicar!H23:H25) -> 20800 | H8: =MIN(Precios_Para_Comunicar!I23:I25) -> 20700 | I8: =MIN(Precios_Para_Comunicar!J23:J25) -> 20500 | J8: =MIN(Precios_Para_Comunicar!K23:K25) -> 20300 | K8: =MIN(Precios_Para_Comunicar!L23:L25) -> 20100 | L8: =MIN(Precios_Para_Comunicar!M23:M25) -> 0.12980769 | M8: =MAX(Precios_Para_Comunicar!Q23:Q25) -> 0.099502488 | N8: 5-9 u | O8: 10-20 u | P8: 30-99 u | Q8: 100+ u

Sheet Plan_Precios_Futuro
A1: PLAN DE PRECIOS A FUTURO — Calculadora dinámica de subas (B2C + tiers partners)
A2: Editá los márgenes objetivo (celdas azules). Los precios sugeridos recalculan solos. Costos linkeados a Resumen_por_Producto (recalculan si cambia Dreamfull).
A4: INPUTS — Margen objetivo por tier (editable)
A5: Tier | B5: Margen objetivo % | C5: Criterio / racional
A6: B2C | B6: mantener actual | C6: Retail ya sano (~47%); subir solo para conservar el margen % actual
A7: Partner (1u) | B7: 0.3 | C7: Compra chica, sostiene margen alto
A8: Starter (5-9u) | B8: 0.26 | C8: Atractivo, deja colchón p/ads
A9: Pro (10-20u) | B9: 0.22 | C9: Volumen medio
A10: Drop (30-99u) | B10: 0.18 | C10: Cubre ads + parte de envío bonificado
A11: Bulk (100+u) | B11: 0.14 | C11: Piso para no quedar en 0-7% como hoy
A13: RECOMENDACIONES POR PRODUCTO | K13: PRECIOS SUGERIDOS POR TIER (para alcanzar el margen objetivo de los inputs) | T13: MARGEN ACTUAL — PEOR CASO (cliente pide el color de mayor costo). Precio único al cliente vs costo del color más caro.
A14: Producto | B14: Costo base | C14: B2C actual | D14: B2C margen% actual | E14: B2C sugerido | F14: Suba B2C % | H14: Costo anterior (ref) | I14: B2C margen% previo | K14: Producto | L14: Partner sug. | M14: Starter sug. | N14: Pro sug. | O14: Drop sug. | P14: Bulk sug. | R14: Observación | T14: Producto | U14: Partner | V14: Starter | W14: Pro | X14: Drop | Y14: Bulk
A15: =Resumen_por_Producto!B2 -> Buzo Cuello Redondo | B15: =Resumen_por_Producto!D2 -> 28170 | C15: =Resumen_por_Producto!E2 -> 43000 | D15: =(C15-B15)/C15 -> 0.34488372 | E15: =ROUND(B15/(1-I15),-2) -> 46300 | F15: =E15/C15-1 -> 0.076744186 | H15: 26170 | I15: =(C15-H15)/C15 -> 0.39139535 | K15: =A15 -> Buzo Cuello Redondo | L15: =ROUND($B15/(1-$B$7),-2) -> 40200 | M15: =ROUND($B15/(1-$B$8),-2) -> 38100 | N15: =ROUND($B15/(1-$B$9),-2) -> 36100 | O15: =ROUND($B15/(1-$B$10),-2) -> 34400 | P15: =ROUND($B15/(1-$B$11),-2) -> 32800 | R15: =IF(F15>0.25,"Suba B2C fuerte: evaluar escalonar",IF(F15>0.12,"Suba B2C moderada","Suba B2C leve, OK")) -> Suba B2C leve, OK | T15: =A15 -> Buzo Cuello Redondo | U15: =(Resumen_por_Producto!G2-Resumen_por_Producto!$D2)/Resumen_por_Producto!G2 -> 0.12515528 | V15: =(Resumen_por_Producto!H2-Resumen_por_Producto!$D2)/Resumen_por_Producto!H2 -> 0.097115385 | W15: =(Resumen_por_Producto!I2-Resumen_por_Producto!$D2)/Resumen_por_Producto!I2 -> 0.067218543 | X15: =(Resumen_por_Producto!J2-Resumen_por_Producto!$D2)/Resumen_por_Producto!J2 -> 0.035273973 | Y15: =(Resumen_por_Producto!K2-Resumen_por_Producto!$D2)/Resumen_por_Producto!K2 -> 0.0010638298
A16: =Resumen_por_Producto!B3 -> Buzo Hoodie Unisex | B16: =Resumen_por_Producto!D3 -> 30170 | C16: =Resumen_por_Producto!E3 -> 55000 | D16: =(C16-B16)/C16 -> 0.45145455 | E16: =ROUND(B16/(1-I16),-2) -> 58900 | F16: =E16/C16-1 -> 0.070909091 | H16: 28170 | I16: =(C16-H16)/C16 -> 0.48781818 | K16: =A16 -> Buzo Hoodie Unisex | L16: =ROUND($B16/(1-$B$7),-2) -> 43100 | M16: =ROUND($B16/(1-$B$8),-2) -> 40800 | N16: =ROUND($B16/(1-$B$9),-2) -> 38700 | O16: =ROUND($B16/(1-$B$10),-2) -> 36800 | P16: =ROUND($B16/(1-$B$11),-2) -> 35100 | R16: =IF(F16>0.25,"Suba B2C fuerte: evaluar escalonar",IF(F16>0.12,"Suba B2C moderada","Suba B2C leve, OK")) -> Suba B2C leve, OK | T16: =A16 -> Buzo Hoodie Unisex | U16: =(Resumen_por_Producto!G3-Resumen_por_Producto!$D3)/Resumen_por_Producto!G3 -> 0.22041344 | V16: =(Resumen_por_Producto!H3-Resumen_por_Producto!$D3)/Resumen_por_Producto!H3 -> 0.17568306 | W16: =(Resumen_por_Producto!I3-Resumen_por_Producto!$D3)/Resumen_por_Producto!I3 -> 0.12550725 | X16: =(Resumen_por_Producto!J3-Resumen_por_Producto!$D3)/Resumen_por_Producto!J3 -> 0.06882716 | Y16: =(Resumen_por_Producto!K3-Resumen_por_Producto!$D3)/Resumen_por_Producto!K3 -> 0.004290429
A17: =Resumen_por_Producto!B4 -> Aura Oversize T-Shirt | B17: =Resumen_por_Producto!D4 -> 23470 | C17: =Resumen_por_Producto!E4 -> 31000 | D17: =(C17-B17)/C17 -> 0.24290323 | E17: =ROUND(B17/(1-I17),-2) -> 35500 | F17: =E17/C17-1 -> 0.14516129 | H17: 20496 | I17: =(C17-H17)/C17 -> 0.33883871 | K17: =A17 -> Aura Oversize T-Shirt | L17: =ROUND($B17/(1-$B$7),-2) -> 33500 | M17: =ROUND($B17/(1-$B$8),-2) -> 31700 | N17: =ROUND($B17/(1-$B$9),-2) -> 30100 | O17: =ROUND($B17/(1-$B$10),-2) -> 28600 | P17: =ROUND($B17/(1-$B$11),-2) -> 27300 | R17: =IF(F17>0.25,"Suba B2C fuerte: evaluar escalonar",IF(F17>0.12,"Suba B2C moderada","Suba B2C leve, OK")) -> Suba B2C moderada | T17: =A17 -> Aura Oversize T-Shirt | U17: =(Resumen_por_Producto!G4-Resumen_por_Producto!$D4)/Resumen_por_Producto!G4 -> 0.11766917 | V17: =(Resumen_por_Producto!H4-Resumen_por_Producto!$D4)/Resumen_por_Producto!H4 -> 0.093822394 | W17: =(Resumen_por_Producto!I4-Resumen_por_Producto!$D4)/Resumen_por_Producto!I4 -> 0.064940239 | X17: =(Resumen_por_Producto!J4-Resumen_por_Producto!$D4)/Resumen_por_Producto!J4 -> 0.034156379 | Y17: =(Resumen_por_Producto!K4-Resumen_por_Producto!$D4)/Resumen_por_Producto!K4 -> 0.0055084746
A18: =Resumen_por_Producto!B5 -> Aldea Classic Fit T-Shirt | B18: =Resumen_por_Producto!D5 -> 22670 | C18: =Resumen_por_Producto!E5 -> 28600 | D18: =(C18-B18)/C18 -> 0.20734266 | E18: =ROUND(B18/(1-I18),-2) -> 32900 | F18: =E18/C18-1 -> 0.15034965 | H18: 19696 | I18: =(C18-H18)/C18 -> 0.31132867 | K18: =A18 -> Aldea Classic Fit T-Shirt | L18: =ROUND($B18/(1-$B$7),-2) -> 32400 | M18: =ROUND($B18/(1-$B$8),-2) -> 30600 | N18: =ROUND($B18/(1-$B$9),-2) -> 29100 | O18: =ROUND($B18/(1-$B$10),-2) -> 27600 | P18: =ROUND($B18/(1-$B$11),-2) -> 26400 | R18: =IF(F18>0.25,"Suba B2C fuerte: evaluar escalonar",IF(F18>0.12,"Suba B2C moderada","Suba B2C leve, OK")) -> Suba B2C moderada | T18: =A18 -> Aldea Classic Fit T-Shirt | U18: =(Resumen_por_Producto!G5-Resumen_por_Producto!$D5)/Resumen_por_Producto!G5 -> 0.12131783 | V18: =(Resumen_por_Producto!H5-Resumen_por_Producto!$D5)/Resumen_por_Producto!H5 -> 0.096812749 | W18: =(Resumen_por_Producto!I5-Resumen_por_Producto!$D5)/Resumen_por_Producto!I5 -> 0.070901639 | X18: =(Resumen_por_Producto!J5-Resumen_por_Producto!$D5)/Resumen_por_Producto!J5 -> 0.047478992 | Y18: =(Resumen_por_Producto!K5-Resumen_por_Producto!$D5)/Resumen_por_Producto!K5 -> 0.03940678
A19: =Resumen_por_Producto!B6 -> Remera Clásica Mujer | B19: =Resumen_por_Producto!D6 -> 22670 | C19: =Resumen_por_Producto!E6 -> 28600 | D19: =(C19-B19)/C19 -> 0.20734266 | E19: =ROUND(B19/(1-I19),-2) -> 32900 | F19: =E19/C19-1 -> 0.15034965 | H19: 19696 | I19: =(C19-H19)/C19 -> 0.31132867 | K19: =A19 -> Remera Clásica Mujer | L19: =ROUND($B19/(1-$B$7),-2) -> 32400 | M19: =ROUND($B19/(1-$B$8),-2) -> 30600 | N19: =ROUND($B19/(1-$B$9),-2) -> 29100 | O19: =ROUND($B19/(1-$B$10),-2) -> 27600 | P19: =ROUND($B19/(1-$B$11),-2) -> 26400 | R19: =IF(F19>0.25,"Suba B2C fuerte: evaluar escalonar",IF(F19>0.12,"Suba B2C moderada","Suba B2C leve, OK")) -> Suba B2C moderada | T19: =A19 -> Remera Clásica Mujer | U19: =(Resumen_por_Producto!G6-Resumen_por_Producto!$D6)/Resumen_por_Producto!G6 -> 0.12131783 | V19: =(Resumen_por_Producto!H6-Resumen_por_Producto!$D6)/Resumen_por_Producto!H6 -> 0.096812749 | W19: =(Resumen_por_Producto!I6-Resumen_por_Producto!$D6)/Resumen_por_Producto!I6 -> 0.070901639 | X19: =(Resumen_por_Producto!J6-Resumen_por_Producto!$D6)/Resumen_por_Producto!J6 -> 0.047478992 | Y19: =(Resumen_por_Producto!K6-Resumen_por_Producto!$D6)/Resumen_por_Producto!K6 -> 0.03940678
A20: =Resumen_por_Producto!B7 -> Remera Crop Mujer | B20: =Resumen_por_Producto!D7 -> 18100 | C20: =Resumen_por_Producto!E7 -> 23500 | D20: =(C20-B20)/C20 -> 0.22978723 | E20: =ROUND(B20/(1-I20),-2) -> 28100 | F20: =E20/C20-1 -> 0.19574468 | H20: 15156 | I20: =(C20-H20)/C20 -> 0.35506383 | K20: =A20 -> Remera Crop Mujer | L20: =ROUND($B20/(1-$B$7),-2) -> 25900 | M20: =ROUND($B20/(1-$B$8),-2) -> 24500 | N20: =ROUND($B20/(1-$B$9),-2) -> 23200 | O20: =ROUND($B20/(1-$B$10),-2) -> 22100 | P20: =ROUND($B20/(1-$B$11),-2) -> 21000 | R20: =IF(F20>0.25,"Suba B2C fuerte: evaluar escalonar",IF(F20>0.12,"Suba B2C moderada","Suba B2C leve, OK")) -> Suba B2C moderada | T20: =A20 -> Remera Crop Mujer | U20: =(Resumen_por_Producto!G7-Resumen_por_Producto!$D7)/Resumen_por_Producto!G7 -> 0.12980769 | V20: =(Resumen_por_Producto!H7-Resumen_por_Producto!$D7)/Resumen_por_Producto!H7 -> 0.10837438 | W20: =(Resumen_por_Producto!I7-Resumen_por_Producto!$D7)/Resumen_por_Producto!I7 -> 0.085858586 | X20: =(Resumen_por_Producto!J7-Resumen_por_Producto!$D7)/Resumen_por_Producto!J7 -> 0.062176166 | Y20: =(Resumen_por_Producto!K7-Resumen_por_Producto!$D7)/Resumen_por_Producto!K7 -> 0.042328042
A21: =Resumen_por_Producto!B8 -> Musculosa Bali | B21: =Resumen_por_Producto!D8 -> 18100 | C21: =Resumen_por_Producto!E8 -> 21800 | D21: =(C21-B21)/C21 -> 0.16972477 | E21: =ROUND(B21/(1-I21),-2) -> 30100 | F21: =E21/C21-1 -> 0.38073394 | H21: 13096 | I21: =(C21-H21)/C21 -> 0.39926606 | K21: =A21 -> Musculosa Bali | L21: =ROUND($B21/(1-$B$7),-2) -> 25900 | M21: =ROUND($B21/(1-$B$8),-2) -> 24500 | N21: =ROUND($B21/(1-$B$9),-2) -> 23200 | O21: =ROUND($B21/(1-$B$10),-2) -> 22100 | P21: =ROUND($B21/(1-$B$11),-2) -> 21000 | R21: =IF(F21>0.25,"Suba B2C fuerte: evaluar escalonar",IF(F21>0.12,"Suba B2C moderada","Suba B2C leve, OK")) -> Suba B2C fuerte: evaluar escalonar | T21: =A21 -> Musculosa Bali | U21: =(Resumen_por_Producto!G8-Resumen_por_Producto!$D8)/Resumen_por_Producto!G8 -> 0.12980769 | V21: =(Resumen_por_Producto!H8-Resumen_por_Producto!$D8)/Resumen_por_Producto!H8 -> 0.12560386 | W21: =(Resumen_por_Producto!I8-Resumen_por_Producto!$D8)/Resumen_por_Producto!I8 -> 0.11707317 | X21: =(Resumen_por_Producto!J8-Resumen_por_Producto!$D8)/Resumen_por_Producto!J8 -> 0.10837438 | Y21: =(Resumen_por_Producto!K8-Resumen_por_Producto!$D8)/Resumen_por_Producto!K8 -> 0.099502488
T23: MARGEN ACTUAL — MEJOR CASO (cliente pide el color de menor costo).
A24: CÓMO USAR ESTA TAB | T24: Producto | U24: Partner | V24: Starter | W24: Pro | X24: Drop | Y24: Bulk
